[2023-09-13T13:16:20.860+0000] {taskinstance.py:1157} INFO - Dependencies all met for dep_context=non-requeueable deps ti=<TaskInstance: realtime_elt.upload_file_to_s3 manual__2023-09-13T13:16:09.735573+00:00 [queued]>
[2023-09-13T13:16:20.865+0000] {taskinstance.py:1157} INFO - Dependencies all met for dep_context=requeueable deps ti=<TaskInstance: realtime_elt.upload_file_to_s3 manual__2023-09-13T13:16:09.735573+00:00 [queued]>
[2023-09-13T13:16:20.866+0000] {taskinstance.py:1359} INFO - Starting attempt 1 of 1
[2023-09-13T13:16:20.873+0000] {taskinstance.py:1380} INFO - Executing <Task(_PythonDecoratedOperator): upload_file_to_s3> on 2023-09-13 13:16:09.735573+00:00
[2023-09-13T13:16:20.876+0000] {standard_task_runner.py:57} INFO - Started process 200 to run task
[2023-09-13T13:16:20.879+0000] {standard_task_runner.py:84} INFO - Running: ['***', 'tasks', 'run', 'realtime_elt', 'upload_file_to_s3', 'manual__2023-09-13T13:16:09.735573+00:00', '--job-id', '22', '--raw', '--subdir', 'DAGS_FOLDER/realtime_elt.py', '--cfg-path', '/tmp/tmp0uj1bn8_']
[2023-09-13T13:16:20.881+0000] {standard_task_runner.py:85} INFO - Job 22: Subtask upload_file_to_s3
[2023-09-13T13:16:20.908+0000] {task_command.py:415} INFO - Running <TaskInstance: realtime_elt.upload_file_to_s3 manual__2023-09-13T13:16:09.735573+00:00 [running]> on host 6908241070e1
[2023-09-13T13:16:20.957+0000] {taskinstance.py:1660} INFO - Exporting env vars: AIRFLOW_CTX_DAG_OWNER='***' AIRFLOW_CTX_DAG_ID='realtime_elt' AIRFLOW_CTX_TASK_ID='upload_file_to_s3' AIRFLOW_CTX_EXECUTION_DATE='2023-09-13T13:16:09.735573+00:00' AIRFLOW_CTX_TRY_NUMBER='1' AIRFLOW_CTX_DAG_RUN_ID='manual__2023-09-13T13:16:09.735573+00:00'
[2023-09-13T13:16:21.098+0000] {taskinstance.py:1935} ERROR - Task failed with exception
Traceback (most recent call last):
  File "/home/airflow/.local/lib/python3.8/site-packages/airflow/decorators/base.py", line 221, in execute
    return_value = super().execute(context)
  File "/home/airflow/.local/lib/python3.8/site-packages/airflow/operators/python.py", line 192, in execute
    return_value = self.execute_callable()
  File "/home/airflow/.local/lib/python3.8/site-packages/airflow/operators/python.py", line 209, in execute_callable
    return self.python_callable(*self.op_args, **self.op_kwargs)
  File "/opt/airflow/dags/realtime_elt.py", line 96, in upload_file_to_s3
    response = s3_client.upload_file(file_name, bucket, object_name)
  File "/home/airflow/.local/lib/python3.8/site-packages/boto3/s3/inject.py", line 143, in upload_file
    return transfer.upload_file(
  File "/home/airflow/.local/lib/python3.8/site-packages/boto3/s3/transfer.py", line 292, in upload_file
    future.result()
  File "/home/airflow/.local/lib/python3.8/site-packages/s3transfer/futures.py", line 103, in result
    return self._coordinator.result()
  File "/home/airflow/.local/lib/python3.8/site-packages/s3transfer/futures.py", line 266, in result
    raise self._exception
  File "/home/airflow/.local/lib/python3.8/site-packages/s3transfer/tasks.py", line 269, in _main
    self._submit(transfer_future=transfer_future, **kwargs)
  File "/home/airflow/.local/lib/python3.8/site-packages/s3transfer/upload.py", line 585, in _submit
    upload_input_manager.provide_transfer_size(transfer_future)
  File "/home/airflow/.local/lib/python3.8/site-packages/s3transfer/upload.py", line 244, in provide_transfer_size
    self._osutil.get_file_size(transfer_future.meta.call_args.fileobj)
  File "/home/airflow/.local/lib/python3.8/site-packages/s3transfer/utils.py", line 247, in get_file_size
    return os.path.getsize(filename)
  File "/usr/local/lib/python3.8/genericpath.py", line 50, in getsize
    return os.stat(filename).st_size
FileNotFoundError: [Errno 2] No such file or directory: '/opt/airflow/data/sensors_realtime.parquet'
[2023-09-13T13:16:21.104+0000] {taskinstance.py:1398} INFO - Marking task as FAILED. dag_id=realtime_elt, task_id=upload_file_to_s3, execution_date=20230913T131609, start_date=20230913T131620, end_date=20230913T131621
[2023-09-13T13:16:21.111+0000] {standard_task_runner.py:104} ERROR - Failed to execute job 22 for task upload_file_to_s3 ([Errno 2] No such file or directory: '/opt/airflow/data/sensors_realtime.parquet'; 200)
[2023-09-13T13:16:21.130+0000] {local_task_job_runner.py:228} INFO - Task exited with return code 1
[2023-09-13T13:16:21.141+0000] {taskinstance.py:2776} INFO - 0 downstream tasks scheduled from follow-on schedule check
