[2023-09-21T21:05:26.237+0000] {taskinstance.py:1157} INFO - Dependencies all met for dep_context=non-requeueable deps ti=<TaskInstance: realtime_elt.upload_sensor_data_to_s3 manual__2023-09-21T21:05:15.080118+00:00 [queued]>
[2023-09-21T21:05:26.242+0000] {taskinstance.py:1157} INFO - Dependencies all met for dep_context=requeueable deps ti=<TaskInstance: realtime_elt.upload_sensor_data_to_s3 manual__2023-09-21T21:05:15.080118+00:00 [queued]>
[2023-09-21T21:05:26.242+0000] {taskinstance.py:1359} INFO - Starting attempt 1 of 1
[2023-09-21T21:05:26.249+0000] {taskinstance.py:1380} INFO - Executing <Task(_PythonDecoratedOperator): upload_sensor_data_to_s3> on 2023-09-21 21:05:15.080118+00:00
[2023-09-21T21:05:26.252+0000] {standard_task_runner.py:57} INFO - Started process 3359 to run task
[2023-09-21T21:05:26.254+0000] {standard_task_runner.py:84} INFO - Running: ['***', 'tasks', 'run', 'realtime_elt', 'upload_sensor_data_to_s3', 'manual__2023-09-21T21:05:15.080118+00:00', '--job-id', '57', '--raw', '--subdir', 'DAGS_FOLDER/realtime_elt.py', '--cfg-path', '/tmp/tmpoyw7sbas']
[2023-09-21T21:05:26.256+0000] {standard_task_runner.py:85} INFO - Job 57: Subtask upload_sensor_data_to_s3
[2023-09-21T21:05:26.280+0000] {task_command.py:415} INFO - Running <TaskInstance: realtime_elt.upload_sensor_data_to_s3 manual__2023-09-21T21:05:15.080118+00:00 [running]> on host f7858b6ac50d
[2023-09-21T21:05:26.339+0000] {taskinstance.py:1660} INFO - Exporting env vars: AIRFLOW_CTX_DAG_OWNER='***' AIRFLOW_CTX_DAG_ID='realtime_elt' AIRFLOW_CTX_TASK_ID='upload_sensor_data_to_s3' AIRFLOW_CTX_EXECUTION_DATE='2023-09-21T21:05:15.080118+00:00' AIRFLOW_CTX_TRY_NUMBER='1' AIRFLOW_CTX_DAG_RUN_ID='manual__2023-09-21T21:05:15.080118+00:00'
[2023-09-21T21:05:26.340+0000] {taskinstance.py:1935} ERROR - Task failed with exception
Traceback (most recent call last):
  File "/home/airflow/.local/lib/python3.8/site-packages/airflow/decorators/base.py", line 221, in execute
    return_value = super().execute(context)
  File "/home/airflow/.local/lib/python3.8/site-packages/airflow/operators/python.py", line 192, in execute
    return_value = self.execute_callable()
  File "/home/airflow/.local/lib/python3.8/site-packages/airflow/operators/python.py", line 209, in execute_callable
    return self.python_callable(*self.op_args, **self.op_kwargs)
  File "/opt/airflow/dags/realtime_elt.py", line 77, in upload_sensor_data_to_s3
    object_name = os.path.basename(file_name)
UnboundLocalError: local variable 'file_name' referenced before assignment
[2023-09-21T21:05:26.345+0000] {taskinstance.py:1398} INFO - Marking task as FAILED. dag_id=realtime_elt, task_id=upload_sensor_data_to_s3, execution_date=20230921T210515, start_date=20230921T210526, end_date=20230921T210526
[2023-09-21T21:05:26.351+0000] {standard_task_runner.py:104} ERROR - Failed to execute job 57 for task upload_sensor_data_to_s3 (local variable 'file_name' referenced before assignment; 3359)
[2023-09-21T21:05:26.386+0000] {local_task_job_runner.py:228} INFO - Task exited with return code 1
[2023-09-21T21:05:26.401+0000] {taskinstance.py:2776} INFO - 0 downstream tasks scheduled from follow-on schedule check
