[2023-09-13T13:08:22.153+0000] {taskinstance.py:1157} INFO - Dependencies all met for dep_context=non-requeueable deps ti=<TaskInstance: realtime_elt.upload_file_to_s3 manual__2023-09-13T13:08:21.331393+00:00 [queued]>
[2023-09-13T13:08:22.158+0000] {taskinstance.py:1157} INFO - Dependencies all met for dep_context=requeueable deps ti=<TaskInstance: realtime_elt.upload_file_to_s3 manual__2023-09-13T13:08:21.331393+00:00 [queued]>
[2023-09-13T13:08:22.158+0000] {taskinstance.py:1359} INFO - Starting attempt 1 of 1
[2023-09-13T13:08:22.165+0000] {taskinstance.py:1380} INFO - Executing <Task(_PythonDecoratedOperator): upload_file_to_s3> on 2023-09-13 13:08:21.331393+00:00
[2023-09-13T13:08:22.168+0000] {standard_task_runner.py:57} INFO - Started process 360 to run task
[2023-09-13T13:08:22.170+0000] {standard_task_runner.py:84} INFO - Running: ['***', 'tasks', 'run', 'realtime_elt', 'upload_file_to_s3', 'manual__2023-09-13T13:08:21.331393+00:00', '--job-id', '16', '--raw', '--subdir', 'DAGS_FOLDER/realtime_elt.py', '--cfg-path', '/tmp/tmpkh35ou4a']
[2023-09-13T13:08:22.172+0000] {standard_task_runner.py:85} INFO - Job 16: Subtask upload_file_to_s3
[2023-09-13T13:08:22.199+0000] {task_command.py:415} INFO - Running <TaskInstance: realtime_elt.upload_file_to_s3 manual__2023-09-13T13:08:21.331393+00:00 [running]> on host 1186b8b85817
[2023-09-13T13:08:22.256+0000] {taskinstance.py:1660} INFO - Exporting env vars: AIRFLOW_CTX_DAG_OWNER='***' AIRFLOW_CTX_DAG_ID='realtime_elt' AIRFLOW_CTX_TASK_ID='upload_file_to_s3' AIRFLOW_CTX_EXECUTION_DATE='2023-09-13T13:08:21.331393+00:00' AIRFLOW_CTX_TRY_NUMBER='1' AIRFLOW_CTX_DAG_RUN_ID='manual__2023-09-13T13:08:21.331393+00:00'
[2023-09-13T13:08:22.669+0000] {taskinstance.py:1935} ERROR - Task failed with exception
Traceback (most recent call last):
  File "/home/airflow/.local/lib/python3.8/site-packages/botocore/httpsession.py", line 465, in send
    urllib_response = conn.urlopen(
  File "/home/airflow/.local/lib/python3.8/site-packages/urllib3/connectionpool.py", line 714, in urlopen
    httplib_response = self._make_request(
  File "/home/airflow/.local/lib/python3.8/site-packages/urllib3/connectionpool.py", line 415, in _make_request
    conn.request(method, url, **httplib_request_kw)
  File "/home/airflow/.local/lib/python3.8/site-packages/botocore/awsrequest.py", line 96, in request
    rval = super().request(method, url, body, headers, *args, **kwargs)
  File "/home/airflow/.local/lib/python3.8/site-packages/urllib3/connection.py", line 244, in request
    super(HTTPConnection, self).request(method, url, body=body, headers=headers)
  File "/usr/local/lib/python3.8/http/client.py", line 1256, in request
    self._send_request(method, url, body, headers, encode_chunked)
  File "/usr/local/lib/python3.8/http/client.py", line 1297, in _send_request
    self.putheader(hdr, value)
  File "/home/airflow/.local/lib/python3.8/site-packages/urllib3/connection.py", line 224, in putheader
    _HTTPConnection.putheader(self, header, *values)
  File "/usr/local/lib/python3.8/http/client.py", line 1234, in putheader
    raise ValueError('Invalid header value %r' % (values[i],))
ValueError: Invalid header value b'AWS4-HMAC-SHA256 Credential=AKIA3VSYQ5F4NRJDROAC\n/20230913/us-east-1/s3/aws4_request, SignedHeaders=content-md5;host;x-amz-content-sha256;x-amz-date, Signature=b4ab544b4997aaf2201bd5790d6fc922899e9d13d1a2219cc0fb67f8d70c60fe'

During handling of the above exception, another exception occurred:

Traceback (most recent call last):
  File "/home/airflow/.local/lib/python3.8/site-packages/airflow/decorators/base.py", line 221, in execute
    return_value = super().execute(context)
  File "/home/airflow/.local/lib/python3.8/site-packages/airflow/operators/python.py", line 192, in execute
    return_value = self.execute_callable()
  File "/home/airflow/.local/lib/python3.8/site-packages/airflow/operators/python.py", line 209, in execute_callable
    return self.python_callable(*self.op_args, **self.op_kwargs)
  File "/opt/airflow/dags/realtime_elt.py", line 96, in upload_file_to_s3
    response = s3_client.upload_file(file_name, bucket, object_name)
  File "/home/airflow/.local/lib/python3.8/site-packages/boto3/s3/inject.py", line 143, in upload_file
    return transfer.upload_file(
  File "/home/airflow/.local/lib/python3.8/site-packages/boto3/s3/transfer.py", line 292, in upload_file
    future.result()
  File "/home/airflow/.local/lib/python3.8/site-packages/s3transfer/futures.py", line 103, in result
    return self._coordinator.result()
  File "/home/airflow/.local/lib/python3.8/site-packages/s3transfer/futures.py", line 266, in result
    raise self._exception
  File "/home/airflow/.local/lib/python3.8/site-packages/s3transfer/tasks.py", line 139, in __call__
    return self._execute_main(kwargs)
  File "/home/airflow/.local/lib/python3.8/site-packages/s3transfer/tasks.py", line 162, in _execute_main
    return_value = self._main(**kwargs)
  File "/home/airflow/.local/lib/python3.8/site-packages/s3transfer/upload.py", line 758, in _main
    client.put_object(Bucket=bucket, Key=key, Body=body, **extra_args)
  File "/home/airflow/.local/lib/python3.8/site-packages/botocore/client.py", line 535, in _api_call
    return self._make_api_call(operation_name, kwargs)
  File "/home/airflow/.local/lib/python3.8/site-packages/botocore/client.py", line 963, in _make_api_call
    http, parsed_response = self._make_request(
  File "/home/airflow/.local/lib/python3.8/site-packages/botocore/client.py", line 986, in _make_request
    return self._endpoint.make_request(operation_model, request_dict)
  File "/home/airflow/.local/lib/python3.8/site-packages/botocore/endpoint.py", line 119, in make_request
    return self._send_request(request_dict, operation_model)
  File "/home/airflow/.local/lib/python3.8/site-packages/botocore/endpoint.py", line 202, in _send_request
    while self._needs_retry(
  File "/home/airflow/.local/lib/python3.8/site-packages/botocore/endpoint.py", line 354, in _needs_retry
    responses = self._event_emitter.emit(
  File "/home/airflow/.local/lib/python3.8/site-packages/botocore/hooks.py", line 412, in emit
    return self._emitter.emit(aliased_event_name, **kwargs)
  File "/home/airflow/.local/lib/python3.8/site-packages/botocore/hooks.py", line 256, in emit
    return self._emit(event_name, kwargs)
  File "/home/airflow/.local/lib/python3.8/site-packages/botocore/hooks.py", line 239, in _emit
    response = handler(**kwargs)
  File "/home/airflow/.local/lib/python3.8/site-packages/botocore/retryhandler.py", line 207, in __call__
    if self._checker(**checker_kwargs):
  File "/home/airflow/.local/lib/python3.8/site-packages/botocore/retryhandler.py", line 284, in __call__
    should_retry = self._should_retry(
  File "/home/airflow/.local/lib/python3.8/site-packages/botocore/retryhandler.py", line 307, in _should_retry
    return self._checker(
  File "/home/airflow/.local/lib/python3.8/site-packages/botocore/retryhandler.py", line 363, in __call__
    checker_response = checker(
  File "/home/airflow/.local/lib/python3.8/site-packages/botocore/retryhandler.py", line 247, in __call__
    return self._check_caught_exception(
  File "/home/airflow/.local/lib/python3.8/site-packages/botocore/retryhandler.py", line 416, in _check_caught_exception
    raise caught_exception
  File "/home/airflow/.local/lib/python3.8/site-packages/botocore/endpoint.py", line 281, in _do_get_response
    http_response = self._send(request)
  File "/home/airflow/.local/lib/python3.8/site-packages/botocore/endpoint.py", line 377, in _send
    return self.http_session.send(request)
  File "/home/airflow/.local/lib/python3.8/site-packages/botocore/httpsession.py", line 510, in send
    raise HTTPClientError(error=e)
botocore.exceptions.HTTPClientError: An HTTP Client raised an unhandled exception: Invalid header value b'AWS4-HMAC-SHA256 Credential=AKIA3VSYQ5F4NRJDROAC\n/20230913/us-east-1/s3/aws4_request, SignedHeaders=content-md5;host;x-amz-content-sha256;x-amz-date, Signature=b4ab544b4997aaf2201bd5790d6fc922899e9d13d1a2219cc0fb67f8d70c60fe'
[2023-09-13T13:08:22.682+0000] {taskinstance.py:1398} INFO - Marking task as FAILED. dag_id=realtime_elt, task_id=upload_file_to_s3, execution_date=20230913T130821, start_date=20230913T130822, end_date=20230913T130822
[2023-09-13T13:08:22.691+0000] {standard_task_runner.py:104} ERROR - Failed to execute job 16 for task upload_file_to_s3 (An HTTP Client raised an unhandled exception: Invalid header value b'AWS4-HMAC-SHA256 Credential=AKIA3VSYQ5F4NRJDROAC\n/20230913/us-east-1/s3/aws4_request, SignedHeaders=content-md5;host;x-amz-content-sha256;x-amz-date, Signature=b4ab544b4997aaf2201bd5790d6fc922899e9d13d1a2219cc0fb67f8d70c60fe'; 360)
[2023-09-13T13:08:22.703+0000] {local_task_job_runner.py:228} INFO - Task exited with return code 1
[2023-09-13T13:08:22.713+0000] {taskinstance.py:2776} INFO - 0 downstream tasks scheduled from follow-on schedule check
